<?xml version="1.0" ?>
<!-- =================================================================================== -->
<!-- |    This document was autogenerated by xacro from /home/akshay/Flexcraft/active_vision_ws/src/agent_models/abb_l515_model/abb_l515_description/urdf/abb_l515.xacro | -->
<!-- |    EDITING THIS FILE BY HAND IS NOT RECOMMENDED                                 | -->
<!-- =================================================================================== -->
<robot name="abb_l515">
    <!-- Conversion were obtained from http://www.e-paint.co.uk/Lab_values.asp
       unless otherwise stated. -->
    <!-- Conversion were obtained from http://www.e-paint.co.uk/Lab_values.asp
       unless otherwise stated. -->
    <material name="aluminum">
        <color rgba="0.5 0.5 0.5 1" />
    </material>
    <material name="plastic">
        <color rgba="0.1 0.1 0.1 1" />
    </material>
    <!-- this specific plug does not apply to L515 -->
    <!-- link list -->
    <link name="base_link">
        <!-- See note 1 in package.xml about the inertial and mass values -->
        <inertial>
            <mass value="13.7742" />
            <origin xyz="-0.028986 0.000596 0.11273" rpy="0 0 0" />
            <inertia ixx="0.101998" ixy="0.000495482" ixz="0.000311158" iyy="0.13969" iyz="-0.000245375" izz="0.130433" />
        </inertial>
        <collision name="collision">
            <geometry>
                <mesh filename="package://abb_irb1200_support/meshes/irb1200_5_90/collision/base_link.stl" />
            </geometry>
        </collision>
        <visual name="visual">
            <geometry>
                <mesh filename="package://abb_irb1200_support/meshes/irb1200_5_90/visual/base_link.dae" />
            </geometry>
            <material name="">
                <color rgba="1 1 0 1" />
            </material>
        </visual>
    </link>
    <link name="link_1">
        <!-- See note 1 in package.xml about the inertial and mass values -->
        <inertial>
            <mass value="11.8419" />
            <origin xyz="0.000877 -0.000631 -0.062883" rpy="0 0 0" />
            <inertia ixx="0.11194" ixy="-4.54988e-05" ixz="0.000280961" iyy="0.0915159" iyz="-0.000109905" izz="0.0876456" />
        </inertial>
        <collision name="collision">
            <geometry>
                <mesh filename="package://abb_irb1200_support/meshes/irb1200_5_90/collision/link_1.stl" />
            </geometry>
        </collision>
        <visual name="visual">
            <geometry>
                <mesh filename="package://abb_irb1200_support/meshes/irb1200_5_90/visual/link_1.dae" />
            </geometry>
            <material name="">
                <color rgba="1 1 0 1" />
            </material>
        </visual>
    </link>
    <link name="link_2">
        <!-- See note 1 in package.xml about the inertial and mass values -->
        <inertial>
            <mass value="17.5394" />
            <origin xyz="-0.000928 -0.000497 0.250051" rpy="0 0 0" />
            <inertia ixx="0.493558" ixy="1.32136e-05" ixz="0.000209024" iyy="0.462939" iyz="-0.00179901" izz="0.0894214" />
        </inertial>
        <collision name="collision">
            <geometry>
                <mesh filename="package://abb_irb1200_support/meshes/irb1200_5_90/collision/link_2.stl" />
            </geometry>
        </collision>
        <visual name="visual">
            <geometry>
                <mesh filename="package://abb_irb1200_support/meshes/irb1200_5_90/visual/link_2.dae" />
            </geometry>
            <material name="">
                <color rgba="1 1 0 1" />
            </material>
        </visual>
    </link>
    <link name="link_3">
        <!-- See note 1 in package.xml about the inertial and mass values -->
        <inertial>
            <mass value="7.46365" />
            <origin xyz="0.099588 0.001143 0.032333" rpy="0 0 0" />
            <inertia ixx="0.0252424" ixy="0.000142737" ixz="-0.00565542" iyy="0.0906438" iyz="0.000142213" izz="0.0825079" />
        </inertial>
        <collision name="collision">
            <geometry>
                <mesh filename="package://abb_irb1200_support/meshes/irb1200_5_90/collision/link_3.stl" />
            </geometry>
        </collision>
        <visual name="visual">
            <geometry>
                <mesh filename="package://abb_irb1200_support/meshes/irb1200_5_90/visual/link_3.dae" />
            </geometry>
            <material name="">
                <color rgba="1 1 0 1" />
            </material>
        </visual>
    </link>
    <link name="link_4">
        <!-- See note 1 in package.xml about the inertial and mass values -->
        <inertial>
            <mass value="2.74436" />
            <origin xyz="0.381678 0.001261 0.005168" rpy="0 0 0" />
            <inertia ixx="0.00573099" ixy="-0.000131119" ixz="0.000380232" iyy="0.0118352" iyz="-2.26565e-05" izz="0.0114428" />
        </inertial>
        <collision name="collision">
            <geometry>
                <mesh filename="package://abb_irb1200_support/meshes/irb1200_5_90/collision/link_4.stl" />
            </geometry>
        </collision>
        <visual name="visual">
            <geometry>
                <mesh filename="package://abb_irb1200_support/meshes/irb1200_5_90/visual/link_4.dae" />
            </geometry>
            <material name="">
                <color rgba="1 1 0 1" />
            </material>
        </visual>
    </link>
    <link name="link_5">
        <!-- See note 1 in package.xml about the inertial and mass values -->
        <inertial>
            <mass value="0.62953" />
            <origin xyz="0.011197 -0.001056 0.000109" rpy="0 0 0" />
            <inertia ixx="0.000502815" ixy="-1.03173e-05" ixz="-8.74347e-08" iyy="0.00108856" iyz="2.07657e-07" izz="0.000918873" />
        </inertial>
        <collision name="collision">
            <geometry>
                <mesh filename="package://abb_irb1200_support/meshes/irb1200_5_90/collision/link_5.stl" />
            </geometry>
        </collision>
        <visual name="visual">
            <geometry>
                <mesh filename="package://abb_irb1200_support/meshes/irb1200_5_90/visual/link_5.dae" />
            </geometry>
            <material name="">
                <color rgba="1 1 0 1" />
            </material>
        </visual>
    </link>
    <link name="link_6">
        <!-- See note 1 in package.xml about the inertial and mass values -->
        <inertial>
            <mass value="0.137" />
            <origin rpy="0 0 0" xyz="-0.00706 -0.00017 -1.32E-06" />
            <inertia ixx="0.001" ixy="0" ixz="0" iyy="0.001" iyz="0" izz="0.001" />
        </inertial>
        <!-- Meshlab calculated values (below) make gazebo crash when rotating this joint. -->
        <!-- <inertial>
        <mass value="0.00686711"/>
        <origin xyz="-0.00250976 -1.89e-06 0.00010218"/>
        <inertia ixx="1.3517e-06" ixy="-1.21316e-11" ixz="9.18065e-12" iyy="6.89813e-07" iyz="-1.21534e-10" izz="6.90097e-07"/>
      </inertial> -->
        <collision name="collision">
            <geometry>
                <mesh filename="package://abb_irb1200_support/meshes/irb1200_5_90/collision/link_6.stl" />
            </geometry>
        </collision>
        <visual name="visual">
            <geometry>
                <mesh filename="package://abb_irb1200_support/meshes/irb1200_5_90/visual/link_6.dae" />
            </geometry>
            <material name="">
                <color rgba="1 1 0 1" />
            </material>
        </visual>
    </link>
    <!-- end of link list -->
    <!-- joint list -->
    <joint name="joint_1" type="revolute">
        <origin rpy="0 0 0" xyz="0 0 0.3991" />
        <axis xyz="0 0 1" />
        <parent link="base_link" />
        <child link="link_1" />
        <!-- See note 2 in package.xml about effort limits and dynamics values -->
        <limit effort="1000" lower="-2.967" upper="2.967" velocity="5.027" />
        <dynamics damping="50.0" friction="1.0" />
    </joint>
    <joint name="joint_2" type="revolute">
        <origin rpy="0 0 0" xyz="0 0 0" />
        <axis xyz="0 1 0" />
        <parent link="link_1" />
        <child link="link_2" />
        <!-- See note 2 in package.xml about effort limits and dynamics values -->
        <limit effort="1000" lower="-1.745" upper="2.269" velocity="4.189" />
        <dynamics damping="50.0" friction="1.0" />
    </joint>
    <joint name="joint_3" type="revolute">
        <origin rpy="0 0 0" xyz="0 0 0.448" />
        <axis xyz="0 1 0" />
        <parent link="link_2" />
        <child link="link_3" />
        <!-- See note 2 in package.xml about effort limits and dynamics values -->
        <limit effort="1000" lower="-3.491" upper="1.222" velocity="5.236" />
        <dynamics damping="10.0" friction="1.0" />
    </joint>
    <joint name="joint_4" type="revolute">
        <origin rpy="0 0 0" xyz="0 0 0.042" />
        <axis xyz="1 0 0" />
        <parent link="link_3" />
        <child link="link_4" />
        <!-- See note 2 in package.xml about effort limits and dynamics values -->
        <limit effort="1000" lower="-4.712" upper="4.712" velocity="6.981" />
        <dynamics damping="5.0" friction="1.0" />
    </joint>
    <joint name="joint_5" type="revolute">
        <origin rpy="0 0 0" xyz="0.451 0 0" />
        <axis xyz="0 1 0" />
        <parent link="link_4" />
        <child link="link_5" />
        <!-- See note 2 in package.xml about effort limits and dynamics values -->
        <limit effort="1000" lower="-2.269" upper="2.269" velocity="7.069" />
        <dynamics damping="2.0" friction="1.0" />
    </joint>
    <joint name="joint_6" type="revolute">
        <origin rpy="0 0 0" xyz="0.082 0 0" />
        <axis xyz="1 0 0" />
        <parent link="link_5" />
        <child link="link_6" />
        <!-- See note 2 in package.xml about effort limits and dynamics values -->
        <limit effort="1000" lower="-6.283" upper="6.283" velocity="10.472" />
        <dynamics damping="1.0" friction="1.0" />
    </joint>
    <!-- end of joint list -->
    <!-- ROS-Industrial 'base' frame: base_link to ABB World Coordinates transform -->
    <link name="base" />
    <joint name="base_link-base" type="fixed">
        <origin rpy="0 0 0" xyz="0 0 0" />
        <parent link="base_link" />
        <child link="base" />
    </joint>
    <!-- ROS-Industrial 'flange' frame: attachment point for EEF models -->
    <link name="flange" />
    <joint name="joint_6-flange" type="fixed">
        <origin rpy="0 0 0" xyz="0 0 0" />
        <parent link="link_6" />
        <child link="flange" />
    </joint>
    <!-- ROS-Industrial 'tool0' frame: all-zeros tool frame -->
    <link name="tool0" />
    <joint name="link_6-tool0" type="fixed">
        <origin rpy="0 1.5707963267948966 0" xyz="0 0 0" />
        <parent link="flange" />
        <child link="tool0" />
    </joint>
    <!-- transmission list -->
    <transmission name="tran1">
        <type>transmission_interface/SimpleTransmission</type>
        <joint name="joint_1">
            <hardwareInterface>hardware_interface/EffortJointInterface</hardwareInterface>
        </joint>
        <actuator name="motor1">
            <mechanicalReduction>1</mechanicalReduction>
            <hardwareInterface>hardware_interface/EffortJointInterface</hardwareInterface>
        </actuator>
    </transmission>
    <transmission name="tran2">
        <type>transmission_interface/SimpleTransmission</type>
        <joint name="joint_2">
            <hardwareInterface>hardware_interface/EffortJointInterface</hardwareInterface>
        </joint>
        <actuator name="motor2">
            <mechanicalReduction>1</mechanicalReduction>
            <hardwareInterface>hardware_interface/EffortJointInterface</hardwareInterface>
        </actuator>
    </transmission>
    <transmission name="tran3">
        <type>transmission_interface/SimpleTransmission</type>
        <joint name="joint_3">
            <hardwareInterface>hardware_interface/EffortJointInterface</hardwareInterface>
        </joint>
        <actuator name="motor3">
            <mechanicalReduction>1</mechanicalReduction>
            <hardwareInterface>hardware_interface/EffortJointInterface</hardwareInterface>
        </actuator>
    </transmission>
    <transmission name="tran4">
        <type>transmission_interface/SimpleTransmission</type>
        <joint name="joint_4">
            <hardwareInterface>hardware_interface/EffortJointInterface</hardwareInterface>
        </joint>
        <actuator name="motor4">
            <mechanicalReduction>1</mechanicalReduction>
            <hardwareInterface>hardware_interface/EffortJointInterface</hardwareInterface>
        </actuator>
    </transmission>
    <transmission name="tran5">
        <type>transmission_interface/SimpleTransmission</type>
        <joint name="joint_5">
            <hardwareInterface>hardware_interface/EffortJointInterface</hardwareInterface>
        </joint>
        <actuator name="motor5">
            <mechanicalReduction>1</mechanicalReduction>
            <hardwareInterface>hardware_interface/EffortJointInterface</hardwareInterface>
        </actuator>
    </transmission>
    <transmission name="tran6">
        <type>transmission_interface/SimpleTransmission</type>
        <joint name="joint_6">
            <hardwareInterface>hardware_interface/EffortJointInterface</hardwareInterface>
        </joint>
        <actuator name="motor6">
            <mechanicalReduction>1</mechanicalReduction>
            <hardwareInterface>hardware_interface/EffortJointInterface</hardwareInterface>
        </actuator>
    </transmission>
    <!-- end of transmission list -->
    <!-- Gazebo-specific link properties -->
    <gazebo reference="base_link">
        <turnGravityOff>true</turnGravityOff>
        <plugin name="gazebo_ros_control">
            <robotNamespace>/</robotNamespace>
        </plugin>
    </gazebo>
    <gazebo reference="link_1">
        <turnGravityOff>true</turnGravityOff>
    </gazebo>
    <gazebo reference="link_2">
        <turnGravityOff>true</turnGravityOff>
    </gazebo>
    <gazebo reference="link_3">
        <turnGravityOff>true</turnGravityOff>
    </gazebo>
    <gazebo reference="link_4">
        <turnGravityOff>true</turnGravityOff>
    </gazebo>
    <gazebo reference="link_5">
        <turnGravityOff>true</turnGravityOff>
    </gazebo>
    <gazebo reference="link_6">
        <turnGravityOff>true</turnGravityOff>
    </gazebo>
    <!-- Links -->
    <link name="mount_l515_link">
        <inertial>
            <mass value="13.7742" />
            <origin rpy="0 0 0" xyz="0 0 0" />
            <inertia ixx="0.101998" ixy="0.000495482" ixz="0.000311158" iyy="0.13969" iyz="-0.000245375" izz="0.130433" />
        </inertial>
        <collision>
            <geometry>
                <mesh filename="package://abb_l515_description/meshes/camera_mount/collision/camera_mount.stl" scale="0.001 0.001 0.001" />
            </geometry>
        </collision>
        <visual>
            <geometry>
                <mesh filename="package://abb_l515_description/meshes/camera_mount/collision/camera_mount.stl" scale="0.001 0.001 0.001" />
            </geometry>
            <material name="">
                <color rgba="0.9254902 0.9254902 0.9058824 1" />
            </material>
        </visual>
    </link>
    <!-- camera body, with origin at bottom screw mount -->
    <joint name="camera_joint" type="fixed">
        <origin rpy="-0.7662698 -1.5486988 0.7653934" xyz="0.08010264817074966 0.0010650384356907369 0.010552961331817563" />
        <parent link="tool0" />
        <child link="camera_bottom_screw_frame" />
    </joint>
    <link name="camera_bottom_screw_frame" />
    <joint name="camera_link_joint" type="fixed">
        <origin rpy="0 0 0" xyz="0.007500000000000001 0.0 0.021150000000000002" />
        <parent link="camera_bottom_screw_frame" />
        <child link="camera_link" />
    </joint>
    <link name="camera_link">
        <visual>
            <origin rpy="1.5707963267948966 0 1.5707963267948966" xyz="0.0045 0 0.009000000000000001" />
            <geometry>
                <mesh filename="package://realsense2_description/meshes/l515.dae" />
            </geometry>
        </visual>
        <collision>
            <origin rpy="1.5707963267948966 0 1.5707963267948966" xyz="-0.0085 0 0.009000000000000001" />
            <geometry>
                <cylinder length="0.026" radius="0.0305" />
            </geometry>
        </collision>
        <inertial>
            <!-- The following are not reliable values, and should not be used for modeling -->
            <!-- calculated assuming full cylinder as described here: https://en.wikipedia.org/wiki/List_of_moments_of_inertia -->
            <mass value="0.095" />
            <origin xyz="0 0 0" rpy="0 0 0" />
            <inertia ixx="0.000044" ixy="0.0" ixz="0.0" iyy="0.000027" iyz="0.0" izz="0.000027" />
        </inertial>
    </link>
    <joint name="camera_lower_mount_joint" type="fixed">
        <origin rpy="0 0 0" xyz="-0.013999999999999999 0 0.01015" />
        <parent link="camera_bottom_screw_frame" />
        <child link="camera_lower_mount" />
    </joint>
    <link name="camera_lower_mount" />
    <joint name="camera_upper_mount_joint" type="fixed">
        <origin rpy="0 0 0" xyz="-0.013999999999999999 0 0.05015" />
        <parent link="camera_bottom_screw_frame" />
        <child link="camera_upper_mount" />
    </joint>
    <link name="camera_upper_mount" />
    <!-- camera depth joints and links -->
    <joint name="camera_depth_joint" type="fixed">
        <origin rpy="0 0 0" xyz="0 0 0" />
        <parent link="camera_link" />
        <child link="camera_depth_frame" />
    </joint>
    <link name="camera_depth_frame" />
    <joint name="camera_depth_optical_joint" type="fixed">
        <origin rpy="-1.5707963267948966 0 -1.5707963267948966" xyz="0 0 0" />
        <parent link="camera_depth_frame" />
        <child link="camera_depth_optical_frame" />
    </joint>
    <link name="camera_depth_optical_frame" />
    <!-- camera left IR joints and links -->
    <joint name="camera_infra_joint" type="fixed">
        <origin rpy="0 0 0" xyz="0 0.0 0" />
        <parent link="camera_link" />
        <child link="camera_infra_frame" />
    </joint>
    <link name="camera_infra_frame" />
    <joint name="camera_infra_optical_joint" type="fixed">
        <origin rpy="-1.5707963267948966 0 -1.5707963267948966" xyz="0 0 0" />
        <parent link="camera_infra_frame" />
        <child link="camera_infra_optical_frame" />
    </joint>
    <link name="camera_infra_optical_frame" />
    <!-- camera color joints and links -->
    <joint name="camera_color_joint" type="fixed">
        <origin rpy="0 0 0" xyz="0 0 0.024" />
        <parent link="camera_link" />
        <child link="camera_color_frame" />
    </joint>
    <link name="camera_color_frame" />
    <joint name="camera_color_optical_joint" type="fixed">
        <origin rpy="-1.5707963267948966 0 -1.5707963267948966" xyz="0 0 0" />
        <parent link="camera_color_frame" />
        <child link="camera_color_optical_frame" />
    </joint>
    <link name="camera_color_optical_frame" />
    <!-- camera IMU joints and links -->
    <link name="camera_gyro_frame" />
    <link name="camera_gyro_optical_frame" />
    <link name="camera_accel_frame" />
    <link name="camera_accel_optical_frame" />
    <joint name="camera_gyro_joint" type="fixed">
        <origin rpy="-0.006161012 0.020193459 0.016301375" xyz="-0.00410137791186571 -0.0129784867167473 0.00256138201802969" />
        <parent link="camera_color_frame" />
        <child link="camera_gyro_frame" />
    </joint>
    <joint name="camera_gyro_optical_joint" type="fixed">
        <origin rpy="-1.5707963267948966 0 -1.5707963267948966" xyz="0 0 0" />
        <parent link="camera_gyro_frame" />
        <child link="camera_gyro_optical_frame" />
    </joint>
    <joint name="camera_accel_joint" type="fixed">
        <origin rpy="-0.006161012 0.020193459 0.016301375" xyz="-0.00410137791186571 -0.0129784867167473 0.00256138201802969" />
        <parent link="camera_color_frame" />
        <child link="camera_accel_frame" />
    </joint>
    <joint name="camera_accel_optical_joint" type="fixed">
        <origin rpy="-1.5707963267948966 0 -1.5707963267948966" xyz="0 0 0" />
        <parent link="camera_accel_frame" />
        <child link="camera_accel_optical_frame" />
    </joint>
    <!-- Gazebo plugin for depth camera -->
    <gazebo reference="camera_link">
        <material>Gazebo/Wood</material>
        <sensor name="camera" type="depth">
            <pose>0 0 0 0 0 0</pose>
            <update_rate>30</update_rate>
            <always_on>true</always_on>
            <visualize>false</visualize>
            <camera>
                <!-- <horizontal_fov>1.22173</horizontal_fov> -->
                <horizontal_fov>0.698132</horizontal_fov>
                <image>
                    <width>960</width>
                    <height>720</height>
                    <format>R8G8B8</format>
                </image>
                <clip>
                    <near>0.05</near>
                    <far>2.0</far>
                </clip>
            </camera>
            <plugin filename="libgazebo_ros_openni_kinect.so" name="camera_controller">
                <baseline>0.2</baseline>
                <alwaysOn>true</alwaysOn>
                <updateRate>0.0</updateRate>
                <cameraName>camera</cameraName>
                <frameName>camera_color_optical_frame</frameName>
                <imageTopicName>color/image_rect_color</imageTopicName>
                <depthImageTopicName>aligned_depth_to_color/image_raw</depthImageTopicName>
                <pointCloudTopicName>depth_registered/points</pointCloudTopicName>
                <cameraInfoTopicName>color/camera_info</cameraInfoTopicName>
                <depthImageCameraInfoTopicName>aligned_depth_to_color/camera_info</depthImageCameraInfoTopicName>
                <pointCloudCutoff>0.05</pointCloudCutoff>
                <pointCloudCutoffMax>2.0</pointCloudCutoffMax>
                <hackBaseline>0.0</hackBaseline>
                <distortionK1>0.0</distortionK1>
                <distortionK2>0.0</distortionK2>
                <distortionK3>0.0</distortionK3>
                <distortionT1>0.0</distortionT1>
                <distortionT2>0.0</distortionT2>
                <CxPrime>0.0</CxPrime>
                <Cx>0.0</Cx>
                <Cy>0.0</Cy>
                <focalLength>0.0</focalLength>
            </plugin>
        </sensor>
        <turnGravityOff>true</turnGravityOff>
    </gazebo>
    <!-- Connect robot to world. -->
    <link name="world" />
    <joint name="world_to_base_link_joint" type="fixed">
        <origin rpy="0 0 0" xyz="0 0 0.525" />
        <parent link="world" />
        <child link="base_link" />
    </joint>
    <!-- Connect robot to world. -->
    <link name="visual" />
    <joint name="world_to_visual_joint" type="fixed">
        <origin rpy="-1.5707963267948966 0 -1.5707963267948966" xyz="0 0 0" />
        <parent link="world" />
        <child link="visual" />
    </joint>
    <!-- Connect camera mount to arm. -->
    <joint name="$arm_to_mount_joint" type="fixed">
        <origin rpy="-1.5707963267948966 0 1.5707963267948966" xyz="0.032755 0 0" />
        <parent link="tool0" />
        <child link="mount_l515_link" />
    </joint>
    <!-- Plugin for ros_control. -->
    <gazebo>
        <plugin filename="libgazebo_ros_control.so" name="gazebo_ros_control">
            <robotNamespace>/</robotNamespace>
            <robotSimType>gazebo_ros_control/DefaultRobotHWSim</robotSimType>
        </plugin>
    </gazebo>
</robot>

